Workbook
Name FilePath: Helper!$A$1

Sheet Helper
A1: {=LEFT(CELL("filename",A1),FIND("[",CELL("filename",A1))-1)} -> C:\Users\Zsolt\Projects\hungarian-web-accessibility-audit\

Sheet analytical_sample
A1: 2025-06-03 | B1: 2025-06-10 | C1: 2025-06-17 | D1: 2025-06-24 | E1: 2025-07-01 | F1: 2025-07-08 | G1: 2025-07-15 | H1: 2025-07-22 | I1: 2025-07-29 | J1: 2025-08-05 | K1: 2025-08-12 | L1: 2025-08-19 | M1: 2025-08-26 | N1: 2025-09-02 | O1: 2025-09-09 | P1: 2025-09-16 | Q1: 2025-09-23 | R1: 2025-09-30 | S1: 2025-10-07 | T1: 2025-10-14 | U1: 2025-10-21 | V1: 2025-10-28 | W1: 2025-11-04 | X1: 2025-11-11 | Y1: 2025-11-18 | Z1: 2025-11-25 | AA1: 2025-12-02 | AB1: 2025-12-09 | AC1: 2025-12-16 | AD1: 2025-12-23 | AE1: 2025-12-30 | AF1: 2026-01-06 | AG1: 2026-01-13 | AH1: 2026-01-20 | AI1: 2026-01-27 | AJ1: 2026-02-03 | AK1: 2026-02-10 | AL1: 2026-02-17 | AM1: 2026-02-24 | AN1: 2026-03-03 | AO1: 2026-03-10 | AP1: 2026-03-17 | AQ1: 2026-03-24 | AR1: 2026-03-31 | AS1: Átlag
A2: 154 | B2: 162 | C2: 153 | D2: 144 | E2: 140 | F2: 154 | G2: 162 | H2: 154 | I2: 152 | J2: 153 | K2: 139 | L2: 154 | M2: 146 | N2: 156 | O2: 149 | P2: 152 | Q2: 161 | R2: 158 | S2: 141 | T2: 160 | U2: 150 | V2: 164 | W2: 156 | X2: 156 | Y2: 162 | Z2: 144 | AA2: 165 | AB2: 154 | AC2: 150 | AD2: 162 | AE2: 156 | AF2: 149 | AG2: 140 | AH2: 153 | AI2: 164 | AJ2: 160 | AK2: 154 | AL2: 165 | AM2: 156 | AN2: 154 | AO2: 157 | AP2: 146 | AQ2: 165 | AR2: 152 | AS2: 154.04545
A3: 136 | B3: 139 | C3: 155 | D3: 137 | E3: 143 | F3: 147 | G3: 146 | H3: 152 | I3: 146 | J3: 138 | K3: 149 | L3: 146 | M3: 140 | N3: 146 | O3: 147 | P3: 156 | Q3: 139 | R3: 144 | S3: 161 | T3: 154 | U3: 147 | V3: 152 | W3: 139 | X3: 148 | Y3: 151 | Z3: 153 | AA3: 153 | AB3: 146 | AC3: 147 | AD3: 146 | AE3: 146 | AF3: 138 | AG3: 134 | AH3: 118 | AI3: 118 | AJ3: 129 | AK3: 112 | AL3: 117 | AM3: 124 | AN3: 125 | AO3: 124 | AP3: 124 | AQ3: 116 | AR3: 123 | AS3: 139.79545
A4: 174 | B4: 181 | C4: 174 | D4: 174 | E4: 175 | F4: 174 | G4: 174 | H4: 174 | I4: 174 | J4: 176 | K4: 174 | L4: 164 | M4: 164 | N4: 175 | O4: 175 | P4: 175 | Q4: 174 | R4: 175 | S4: 173 | T4: 174 | U4: 172 | V4: 174 | W4: 173 | X4: 180 | Y4: 174 | Z4: 173 | AA4: 168 | AB4: 173 | AC4: 173 | AD4: 130 | AE4: 129 | AF4: 129 | AG4: 130 | AH4: 129 | AI4: 129 | AJ4: 130 | AK4: 135 | AL4: 129 | AM4: 130 | AN4: 135 | AO4: 124 | AP4: 134 | AQ4: 129 | AR4: 2 | AS4: 155.84091
A5: 126 | B5: 123 | C5: 121 | D5: 110 | E5: 121 | F5: 127 | G5: 122 | H5: 124 | I5: 124 | J5: 126 | K5: 124 | L5: 120 | M5: 118 | N5: 119 | O5: 123 | P5: 119 | Q5: 121 | R5: 120 | S5: 117 | T5: 112 | U5: 115 | V5: 116 | W5: 119 | X5: 117 | Y5: 109 | Z5: 116 | AA5: 115 | AB5: 112 | AC5: 124 | AD5: 125 | AE5: 113 | AF5: 117 | AG5: 112 | AH5: 118 | AI5: 114 | AJ5: 118 | AK5: 114 | AL5: 116 | AM5: 107 | AN5: 167 | AO5: 132 | AP5: 179 | AQ5: 142 | AR5: 203 | AS5: 123.56818
A6: 156 | B6: 167 | C6: 150 | D6: 155 | E6: 162 | F6: 159 | G6: 159 | H6: 159 | I6: 158 | J6: 159 | K6: 155 | L6: 147 | M6: 145 | N6: 141 | O6: 138 | P6: 137 | Q6: 139 | R6: 140 | S6: 139 | T6: 140 | U6: 141 | V6: 141 | W6: 136 | X6: 142 | Y6: 141 | Z6: 139 | AA6: 134 | AB6: 140 | AC6: 134 | AD6: 141 | AE6: 137 | AF6: 140 | AG6: 135 | AH6: 131 | AI6: 135 | AJ6: 135 | AK6: 135 | AL6: 134 | AM6: 134 | AN6: 131 | AO6: 135 | AP6: 136 | AQ6: 136 | AR6: 136 | AS6: 142.81818
A7: 230 | B7: 227 | C7: 243 | D7: 105 | E7: 195 | F7: 208 | G7: 139 | H7: 152 | I7: 143 | J7: 163 | K7: 158 | L7: 161 | M7: 161 | N7: 155 | O7: 139 | P7: 140 | Q7: 137 | R7: 149 | S7: 145 | T7: 161 | U7: 134 | V7: 159 | W7: 151 | X7: 160 | Y7: 74 | Z7: 158 | AA7: 158 | AB7: 72 | AC7: 144 | AD7: 144 | AE7: 55 | AF7: 66 | AG7: 67 | AH7: 66 | AI7: 76 | AJ7: 41 | AK7: 75 | AL7: 55 | AM7: 81 | AN7: 81 | AO7: 76 | AP7: 152 | AQ7: 148 | AR7: 147 | AS7: 132.97727
A8: 202 | B8: 185 | C8: 78 | D8: 84 | E8: 97 | F8: 76 | G8: 89 | H8: 74 | I8: 72 | J8: 66 | K8: 66 | L8: 72 | M8: 60 | N8: 30 | O8: 27 | P8: 28 | Q8: 36 | R8: 29 | S8: 28 | T8: 29 | U8: 29 | V8: 31 | W8: 25 | X8: 25 | Y8: 45 | Z8: 29 | AA8: 23 | AB8: 33 | AC8: 23 | AD8: 22 | AE8: 34 | AF8: 44 | AG8: 36 | AH8: 33 | AI8: 26 | AJ8: 26 | AK8: 17 | AL8: 25 | AM8: 24 | AN8: 21 | AO8: 18 | AP8: 21 | AQ8: 20 | AR8: 23 | AS8: 47.295455
A9: 163 | B9: 163 | C9: 163 | D9: 163 | E9: 163 | F9: 163 | G9: 163 | H9: 163 | I9: 163 | J9: 163 | K9: 163 | L9: 163 | M9: 163 | N9: 163 | O9: 163 | P9: 162 | Q9: 162 | R9: 162 | S9: 156 | T9: 162 | U9: 162 | V9: 162 | W9: 162 | X9: 162 | Y9: 162 | Z9: 162 | AA9: 1 | AB9: 1 | AC9: 1 | AD9: 1 | AE9: 1 | AF9: 1 | AG9: 1 | AH9: 1 | AI9: 1 | AJ9: 1 | AK9: 1 | AL9: 1 | AM9: 1 | AN9: 1 | AO9: 1 | AP9: 1 | AQ9: 1 | AR9: 1 | AS9: 96.340909
A10: 76 | B10: 76 | C10: 76 | D10: 76 | E10: 76 | F10: 76 | G10: 76 | H10: 76 | I10: 76 | J10: 76 | K10: 76 | L10: 76 | M10: 76 | N10: 76 | O10: 76 | P10: 76 | Q10: 76 | R10: 76 | S10: 76 | T10: 76 | U10: 76 | V10: 76 | W10: 76 | X10: 76 | Y10: 76 | Z10: 76 | AA10: 76 | AB10: 76 | AC10: 76 | AD10: 76 | AE10: 76 | AF10: 76 | AG10: 76 | AH10: 76 | AI10: 76 | AJ10: 76 | AK10: 76 | AL10: 76 | AM10: 76 | AN10: 76 | AO10: 76 | AP10: 76 | AQ10: 1 | AR10: 1 | AS10: 72.590909
A11: 42 | B11: 42 | C11: 42 | D11: 42 | E11: 42 | F11: 44 | G11: 44 | H11: 43 | I11: 44 | J11: 44 | K11: 44 | L11: 34 | M11: 35 | N11: 35 | O11: 37 | P11: 36 | Q11: 37 | R11: 37 | S11: 36 | T11: 36 | U11: 36 | V11: 37 | W11: 37 | X11: 33 | Y11: 33 | Z11: 34 | AA11: 34 | AB11: 34 | AC11: 35 | AD11: 36 | AE11: 36 | AF11: 35 | AG11: 35 | AH11: 34 | AI11: 35 | AJ11: 35 | AK11: 37 | AL11: 36 | AM11: 37 | AN11: 38 | AO11: 36 | AP11: 37 | AQ11: 33 | AR11: 33 | AS11: 37.318182
A12: 203 | B12: 196 | C12: 200 | D12: 109 | E12: 196 | F12: 199 | G12: 195 | H12: 182 | I12: 188 | J12: 193 | K12: 206 | L12: 205 | M12: 209 | N12: 208 | O12: 187 | P12: 192 | Q12: 197 | R12: 201 | S12: 195 | T12: 219 | U12: 216 | V12: 222 | W12: 233 | X12: 224 | Y12: 141 | Z12: 246 | AA12: 233 | AB12: 125 | AC12: 240 | AD12: 235 | AE12: 131 | AF12: 131 | AG12: 127 | AH12: 132 | AI12: 136 | AJ12: 135 | AK12: 151 | AL12: 151 | AM12: 132 | AN12: 137 | AO12: 144 | AP12: 257 | AQ12: 275 | AR12: 269 | AS12: 188.70455
A13: 620 | B13: 602 | C13: 580 | D13: 568 | E13: 512 | F13: 554 | G13: 572 | H13: 559 | I13: 518 | J13: 539 | K13: 612 | L13: 588 | M13: 587 | N13: 606 | O13: 579 | P13: 588 | Q13: 607 | R13: 591 | S13: 677 | T13: 282 | U13: 329 | V13: 324 | W13: 277 | X13: 315 | Y13: 336 | Z13: 385 | AA13: 310 | AB13: 288 | AC13: 348 | AD13: 275 | AE13: 332 | AF13: 314 | AG13: 299 | AH13: 318 | AI13: 312 | AJ13: 300 | AK13: 283 | AL13: 298 | AM13: 336 | AN13: 321 | AO13: 331 | AP13: 258 | AQ13: 277 | AR13: 308 | AS13: 427.61364
... A710: 19 | B710: 19 | C710: 19 | D710: 19 | E710: 19 | F710: 19 | G710: 19 | H710: 19 | I710: 19 | J710: 19 | K710: 19 | L710: 19 | M710: 19 | N710: 19 | O710: 19 | P710: 19 | Q710: 19 | R710: 19 | S710: 19 | T710: 19 | U710: 19 | V710: 19 | W710: 19 | X710: 19 | Y710: 19 | Z710: 19 | AA710: 19 | AB710: 19 | AC710: 19 | AD710: 19 | AE710: 19 | AF710: 19 | AG710: 19 | AH710: 19 | AI710: 19 | AJ710: 19 | AK710: 19 | AL710: 19 | AM710: 19 | AN710: 20 | AO710: 20 | AP710: 20 | AQ710: 20 | AR710: 20 | AS710: 19.113636

Sheet analytical_sample_p99
A1: Relatív rang | B1: Eredeti rang | C1: Domain | D1: Adószám | E1: Statisztikai számjel | F1: Szakágazat kódja | G1: Szakágazat megnevezése | H1: Alágazat kódja | I1: Alágazat megnevezése | J1: Ágazat kódja | K1: Ágazat megnevezése | L1: Nemzetgazdasági ág kódja | M1: Nemzetgazdasági ág megnevezése | N1: Gazdálkodási forma kódja | O1: Gazdálkodási forma megnevezése | P1: Gazdálkodási forma csoportjának kódja | Q1: Gazdálkodási forma csoportjának megnevezése | R1: Gazdálkodási forma főcsoportjának kódja | S1: Gazdálkodási forma főcsoportjának megnevezése | T1: Székhely szerinti vármegye kódja | U1: Székhely szerinti vármegye megnevezése | V1: Statisztikai régió kódja | W1: Statisztikai régió neve | X1: Statisztikai nagyrégió kódja | Y1: Statisztikai nagyrégió neve | Z1: Alapítás éve | AA1: Létszám | AB1: Nettó árbevétel | AC1: Létszám kód | AD1: Létszám intervallum | AE1: Árbevétel-kategória (kód) | AF1: Árbevétel-kategória (millió Ft) | AG1: Alapítás éve (intervallum) | AH1: KKV | AI1: 2025-06-03 | AJ1: 2025-06-10 | AK1: 2025-06-17 | AL1: 2025-06-24 | AM1: 2025-07-01 | AN1: 2025-07-08 | AO1: 2025-07-15 | AP1: 2025-07-22 | AQ1: 2025-07-29 | AR1: 2025-08-05 | AS1: 2025-08-12 | AT1: 2025-08-19 | AU1: 2025-08-26 | AV1: 2025-09-02 | AW1: 2025-09-09 | AX1: 2025-09-16 | AY1: 2025-09-23 | AZ1: 2025-09-30 | BA1: 2025-10-07 | BB1: 2025-10-14 | BC1: 2025-10-21 | BD1: 2025-10-28 | BE1: 2025-11-04 | BF1: 2025-11-11 | BG1: 2025-11-18 | BH1: 2025-11-25 | BI1: 2025-12-02 | BJ1: 2025-12-09 | BK1: 2025-12-16 | BL1: 2025-12-23 | BM1: 2025-12-30 | BN1: 2026-01-06 | BO1: 2026-01-13 | BP1: 2026-01-20 | BQ1: 2026-01-27 | BR1: 2026-02-03 | BS1: 2026-02-10 | BT1: 2026-02-17 | BU1: 2026-02-24 | BV1: 2026-03-03 | BW1: 2026-03-10 | BX1: 2026-03-17 | BY1: 2026-03-24 | BZ1: 2026-03-31 | CA1: Átlag | CB1: Medián | CC1: Szórás | CD1: Relatív szórás | CE1: Minimum | CF1: Maximum | CG1: Terjedelem | CH1: Különbség | CI1: Különbség abszolútértéke
A2: 1 | B2: 4780 | C2: videa.hu | D2: 24785725-2-44 | E2: 24785725 5812 114 01 | F2: 58.12 | G2: Napilapkiadás | H2: 58.1 | I2: Könyv-, napilapkiadás, egyéb kiadói tevékenység (kivéve: szoftverkiadás) | J2: 58 | K2: Kiadói tevékenység | L2: J | M2: KIADÓI TEVÉKENYSÉG, MŰSORSZOLGÁLTATÁS, TARTALOMSZOLGÁLTATÁS ÉS -TERJESZTÉS | N2: 114 | O2: Részvénytársaság | P2: 11 | Q2: Gazdasági társaság | R2: 1 | S2: Jogi személyiségű vállalkozás | T2: 1 | U2: Budapest | V2: 11 | W2: Budapest | X2: 1 | Y2: Közép-Magyarország | Z2: 2013 | AA2: 1974 | AB2: 57098150000 | AC2: 93 | AD2: 1000-1999 | AE2: C | AF2: 10001 - | AG2: 2011 - 2015 | AH2: nagyvállalat | AI2: 154 | AJ2: 162 | AK2: 153 | AL2: 144 | AM2: 140 | AN2: 154 | AO2: 162 | AP2: 154 | AQ2: 152 | AR2: 153 | AS2: 139 | AT2: 154 | AU2: 146 | AV2: 156 | AW2: 149 | AX2: 152 | AY2: 161 | AZ2: 158 | BA2: 141 | BB2: 160 | BC2: 150 | BD2: 164 | BE2: 156 | BF2: 156 | BG2: 162 | BH2: 144 | BI2: 165 | BJ2: 154 | BK2: 150 | BL2: 162 | BM2: 156 | BN2: 149 | BO2: 140 | BP2: 153 | BQ2: 164 | BR2: 160 | BS2: 154 | BT2: 165 | BU2: 156 | BV2: 154 | BW2: 157 | BX2: 146 | BY2: 165 | BZ2: 152 | CA2: 154.04545 | CB2: 154 | CC2: 7.1461635 | CD2: 0.046389967 | CE2: 139 | CF2: 165 | CG2: 26 | CH2: -2 | CI2: 2
A3: 2 | B3: 5209 | C3: 24.hu | D3: 25087910-2-41 | E3: 25087910 5813 114 01 | F3: 58.13 | G3: Folyóirat, időszaki kiadvány kiadása | H3: 58.1 | I3: Könyv-, napilapkiadás, egyéb kiadói tevékenység (kivéve: szoftverkiadás) | J3: 58 | K3: Kiadói tevékenység | L3: J | M3: KIADÓI TEVÉKENYSÉG, MŰSORSZOLGÁLTATÁS, TARTALOMSZOLGÁLTATÁS ÉS -TERJESZTÉS | N3: 114 | O3: Részvénytársaság | P3: 11 | Q3: Gazdasági társaság | R3: 1 | S3: Jogi személyiségű vállalkozás | T3: 1 | U3: Budapest | V3: 11 | W3: Budapest | X3: 1 | Y3: Közép-Magyarország | Z3: 2014 | AA3: 409 | AB3: 14254790000 | AC3: 82 | AD3: 300-499 | AE3: C | AF3: 10001 - | AG3: 2011 - 2015 | AH3: nagyvállalat | AI3: 136 | AJ3: 139 | AK3: 155 | AL3: 137 | AM3: 143 | AN3: 147 | AO3: 146 | AP3: 152 | AQ3: 146 | AR3: 138 | AS3: 149 | AT3: 146 | AU3: 140 | AV3: 146 | AW3: 147 | AX3: 156 | AY3: 139 | AZ3: 144 | BA3: 161 | BB3: 154 | BC3: 147 | BD3: 152 | BE3: 139 | BF3: 148 | BG3: 151 | BH3: 153 | BI3: 153 | BJ3: 146 | BK3: 147 | BL3: 146 | BM3: 146 | BN3: 138 | BO3: 134 | BP3: 118 | BQ3: 118 | BR3: 129 | BS3: 112 | BT3: 117 | BU3: 124 | BV3: 125 | BW3: 124 | BX3: 124 | BY3: 116 | BZ3: 123 | CA3: 139.79545 | CB3: 145 | CC3: 12.587516 | CD3: 0.090042384 | CE3: 112 | CF3: 161 | CG3: 49 | CH3: -13 | CI3: 13
A4: 3 | B4: 5258 | C4: jofogas.hu | D4: 32606753-2-41 | E4: 32606753 7312 113 01 | F4: 73.12 | G4: Médiareklám | H4: 73.1 | I4: Reklám | J4: 73 | K4: Reklám, piackutatás, PR-tevékenység | L4: N | M4: SZAKMAI, TUDOMÁNYOS, MŰSZAKI TEVÉKENYSÉG | N4: 113 | O4: Korlátolt felelősségű társaság | P4: 11 | Q4: Gazdasági társaság | R4: 1 | S4: Jogi személyiségű vállalkozás | T4: 1 | U4: Budapest | V4: 11 | W4: Budapest | X4: 1 | Y4: Közép-Magyarország | Z4: 2024 | AA4: 58 | AB4: 529480000 | AC4: 50 | AD4: 50-99 | AE4: 5 | AF4: 501 - 700 | AG4: 2021 - 2025 | AH4: középvállalkozás | AI4: 174 | AJ4: 181 | AK4: 174 | AL4: 174 | AM4: 175 | AN4: 174 | AO4: 174 | AP4: 174 | AQ4: 174 | AR4: 176 | AS4: 174 | AT4: 164 | AU4: 164 | AV4: 175 | AW4: 175 | AX4: 175 | AY4: 174 | AZ4: 175 | BA4: 173 | BB4: 174 | BC4: 172 | BD4: 174 | BE4: 173 | BF4: 180 | BG4: 174 | BH4: 173 | BI4: 168 | BJ4: 173 | BK4: 173 | BL4: 130 | BM4: 129 | BN4: 129 | BO4: 130 | BP4: 129 | BQ4: 129 | BR4: 130 | BS4: 135 | BT4: 129 | BU4: 130 | BV4: 135 | BW4: 124 | BX4: 134 | BY4: 129 | BZ4: 2 | CA4: 155.84091 | CB4: 173 | CC4: 31.419845 | CD4: 0.20161487 | CE4: 2 | CF4: 181 | CG4: 179 | CH4: -172 | CI4: 172
A5: 4 | B5: 5338 | C5: idokep.hu | D5: 14940961-2-13 | E5: 14940961 6220 113 13 | F5: 62.2 | G5: Információtechnológiai szaktanácsadás és számítástechnikai eszközök, rendszerek üzemeltetése | H5: 62.2 | I5: Információtechnológiai szaktanácsadás és számítástechnikai eszközök, rendszerek üzemeltetése | J5: 62 | K5: Információtechnológiai szolgáltatás | L5: K | M5: TÁVKÖZLÉS, SZÁMÍTÓGÉPES PROGRAMOZÁS, INFORMÁCIÓTECHNOLÓGIAI SZAKTANÁCSADÁS, SZÁMÍTÁSTECHNIKAI INFRASTRUKTÚRA ÉS EGYÉB INFORMÁCIÓS SZOLGÁLTATÁSOK | N5: 113 | O5: Korlátolt felelősségű társaság | P5: 11 | Q5: Gazdasági társaság | R5: 1 | S5: Jogi személyiségű vállalkozás | T5: 13 | U5: Pest | V5: 12 | W5: Pest | X5: 1 | Y5: Közép-Magyarország | Z5: 2009 | AA5: 12 | AB5: 451240000 | AC5: 30 | AD5: 10-19 | AE5: 4 | AF5: 301 - 500 | AG5: 2006 - 2010 | AH5: kisvállalkozás | AI5: 126 | AJ5: 123 | AK5: 121 | AL5: 110 | AM5: 121 | AN5: 127 | AO5: 122 | AP5: 124 | AQ5: 124 | AR5: 126 | AS5: 124 | AT5: 120 | AU5: 118 | AV5: 119 | AW5: 123 | AX5: 119 | AY5: 121 | AZ5: 120 | BA5: 117 | BB5: 112 | BC5: 115 | BD5: 116 | BE5: 119 | BF5: 117 | BG5: 109 | BH5: 116 | BI5: 115 | BJ5: 112 | BK5: 124 | BL5: 125 | BM5: 113 | BN5: 117 | BO5: 112 | BP5: 118 | BQ5: 114 | BR5: 118 | BS5: 114 | BT5: 116 | BU5: 107 | BV5: 167 | BW5: 132 | BX5: 179 | BY5: 142 | BZ5: 203 | CA5: 123.56818 | CB5: 119 | CC5: 17.865646 | CD5: 0.14458128 | CE5: 107 | CF5: 203 | CG5: 96 | CH5: 77 | CI5: 77
A6: 5 | B6: 5518 | C6: mandiner.hu | D6: 32696242-2-43 | E6: 32696242 5813 573 01 | F6: 58.13 | G6: Folyóirat, időszaki kiadvány kiadása | H6: 58.1 | I6: Könyv-, napilapkiadás, egyéb kiadói tevékenység (kivéve: szoftverkiadás) | J6: 58 | K6: Kiadói tevékenység | L6: J | M6: KIADÓI TEVÉKENYSÉG, MŰSORSZOLGÁLTATÁS, TARTALOMSZOLGÁLTATÁS ÉS -TERJESZTÉS | N6: 573 | O6: Nonprofit részvénytársaság | P6: 57 | Q6: Nonprofit gazdasági társaság | R6: 5 | S6: Jogi személyiségű nonprofit szervezet | T6: 1 | U6: Budapest | V6: 11 | W6: Budapest | X6: 1 | Y6: Közép-Magyarország | Z6: 2024 | AA6: 127 | AC6: 61 | AD6: 100-149 | AE6: 0 | AF6: ismeretlen | AG6: 2021 - 2025 | AI6: 156 | AJ6: 167 | AK6: 150 | AL6: 155 | AM6: 162 | AN6: 159 | AO6: 159 | AP6: 159 | AQ6: 158 | AR6: 159 | AS6: 155 | AT6: 147 | AU6: 145 | AV6: 141 | AW6: 138 | AX6: 137 | AY6: 139 | AZ6: 140 | BA6: 139 | BB6: 140 | BC6: 141 | BD6: 141 | BE6: 136 | BF6: 142 | BG6: 141 | BH6: 139 | BI6: 134 | BJ6: 140 | BK6: 134 | BL6: 141 | BM6: 137 | BN6: 140 | BO6: 135 | BP6: 131 | BQ6: 135 | BR6: 135 | BS6: 135 | BT6: 134 | BU6: 134 | BV6: 131 | BW6: 135 | BX6: 136 | BY6: 136 | BZ6: 136 | CA6: 142.81818 | CB6: 140 | CC6: 9.6936151 | CD6: 0.067873817 | CE6: 131 | CF6: 167 | CG6: 36 | CH6: -20 | CI6: 20
A7: 6 | B7: 5570 | C7: portfolio.hu | D7: 12527052-2-41 | E7: 12527052 6039 114 01 | F7: 60.39 | G7: Egyéb tartalomterjesztési tevékenység | H7: 60.3 | I7: Hírügynökségi és egyéb tartalomterjesztési tevékenység | J7: 60 | K7: Műsor-összeállítás, műsorszolgáltatás, hírügynökségi és egyéb tartalomterjesztési tevékenység | L7: J | M7: KIADÓI TEVÉKENYSÉG, MŰSORSZOLGÁLTATÁS, TARTALOMSZOLGÁLTATÁS ÉS -TERJESZTÉS | N7: 114 | O7: Részvénytársaság | P7: 11 | Q7: Gazdasági társaság | R7: 1 | S7: Jogi személyiségű vállalkozás | T7: 1 | U7: Budapest | V7: 11 | W7: Budapest | X7: 1 | Y7: Közép-Magyarország | Z7: 2000 | AA7: 89 | AB7: 4394160000 | AC7: 50 | AD7: 50-99 | AE7: A | AF7: 4001 - 7000 | AG7: 1996 - 2000 | AH7: középvállalkozás | AI7: 230 | AJ7: 227 | AK7: 243 | AL7: 105 | AM7: 195 | AN7: 208 | AO7: 139 | AP7: 152 | AQ7: 143 | AR7: 163 | AS7: 158 | AT7: 161 | AU7: 161 | AV7: 155 | AW7: 139 | AX7: 140 | AY7: 137 | AZ7: 149 | BA7: 145 | BB7: 161 | BC7: 134 | BD7: 159 | BE7: 151 | BF7: 160 | BG7: 74 | BH7: 158 | BI7: 158 | BJ7: 72 | BK7: 144 | BL7: 144 | BM7: 55 | BN7: 66 | BO7: 67 | BP7: 66 | BQ7: 76 | BR7: 41 | BS7: 75 | BT7: 55 | BU7: 81 | BV7: 81 | BW7: 76 | BX7: 152 | BY7: 148 | BZ7: 147 | CA7: 132.97727 | CB7: 144.5 | CC7: 49.743289 | CD7: 0.37407362 | CE7: 41 | CF7: 243 | CG7: 202 | CH7: -83 | CI7: 83
A8: 7 | B8: 5867 | C8: hvg.hu | D8: 10226353-2-41 | E8: 10226353 5813 114 01 | F8: 58.13 | G8: Folyóirat, időszaki kiadvány kiadása | H8: 58.1 | I8: Könyv-, napilapkiadás, egyéb kiadói tevékenység (kivéve: szoftverkiadás) | J8: 58 | K8: Kiadói tevékenység | L8: J | M8: KIADÓI TEVÉKENYSÉG, MŰSORSZOLGÁLTATÁS, TARTALOMSZOLGÁLTATÁS ÉS -TERJESZTÉS | N8: 114 | O8: Részvénytársaság | P8: 11 | Q8: Gazdasági társaság | R8: 1 | S8: Jogi személyiségű vállalkozás | T8: 1 | U8: Budapest | V8: 11 | W8: Budapest | X8: 1 | Y8: Közép-Magyarország | Z8: 1989 | AA8: 194 | AB8: 5150780000 | AC8: 62 | AD8: 150-199 | AE8: A | AF8: 4001 - 7000 | AG8: 1986 - 1990 | AH8: középvállalkozás | AI8: 202 | AJ8: 185 | AK8: 78 | AL8: 84 | AM8: 97 | AN8: 76 | AO8: 89 | AP8: 74 | AQ8: 72 | AR8: 66 | AS8: 66 | AT8: 72 | AU8: 60 | AV8: 30 | AW8: 27 | AX8: 28 | AY8: 36 | AZ8: 29 | BA8: 28 | BB8: 29 | BC8: 29 | BD8: 31 | BE8: 25 | BF8: 25 | BG8: 45 | BH8: 29 | BI8: 23 | BJ8: 33 | BK8: 23 | BL8: 22 | BM8: 34 | BN8: 44 | BO8: 36 | BP8: 33 | BQ8: 26 | BR8: 26 | BS8: 17 | BT8: 25 | BU8: 24 | BV8: 21 | BW8: 18 | BX8: 21 | BY8: 20 | BZ8: 23 | CA8: 47.295455 | CB8: 29.5 | CC8: 39.233102 | CD8: 0.82953218 | CE8: 17 | CF8: 202 | CG8: 185 | CH8: -179 | CI8: 179
A9: 8 | B9: 5910 | C9: hasznaltauto.hu | D9: 14918618-2-41 | E9: 14918618 7312 113 01 | F9: 73.12 | G9: Médiareklám | H9: 73.1 | I9: Reklám | J9: 73 | K9: Reklám, piackutatás, PR-tevékenység | L9: N | M9: SZAKMAI, TUDOMÁNYOS, MŰSZAKI TEVÉKENYSÉG | N9: 113 | O9: Korlátolt felelősségű társaság | P9: 11 | Q9: Gazdasági társaság | R9: 1 | S9: Jogi személyiségű vállalkozás | T9: 1 | U9: Budapest | V9: 11 | W9: Budapest | X9: 1 | Y9: Közép-Magyarország | Z9: 2009 | AA9: 66 | AB9: 5514400000 | AC9: 50 | AD9: 50-99 | AE9: A | AF9: 4001 - 7000 | AG9: 2006 - 2010 | AH9: középvállalkozás | AI9: 163 | AJ9: 163 | AK9: 163 | AL9: 163 | AM9: 163 | AN9: 163 | AO9: 163 | AP9: 163 | AQ9: 163 | AR9: 163 | AS9: 163 | AT9: 163 | AU9: 163 | AV9: 163 | AW9: 163 | AX9: 162 | AY9: 162 | AZ9: 162 | BA9: 156 | BB9: 162 | BC9: 162 | BD9: 162 | BE9: 162 | BF9: 162 | BG9: 162 | BH9: 162 | BI9: 1 | BJ9: 1 | BK9: 1 | BL9: 1 | BM9: 1 | BN9: 1 | BO9: 1 | BP9: 1 | BQ9: 1 | BR9: 1 | BS9: 1 | BT9: 1 | BU9: 1 | BV9: 1 | BW9: 1 | BX9: 1 | BY9: 1 | BZ9: 1 | CA9: 96.340909 | CB9: 162 | CC9: 80.252492 | CD9: 0.83300534 | CE9: 1 | CF9: 163 | CG9: 162 | CH9: -162 | CI9: 162
A10: 9 | B10: 6253 | C10: gyakorikerdesek.hu | D10: 14435986-2-13 | E10: 14435986 6310 113 13 | F10: 63.1 | G10: Számítástechnikai infrastruktúra, adatfeldolgozás, tárhelyszolgáltatás és kapcsolódó szolgáltatások | H10: 63.1 | I10: Számítástechnikai infrastruktúra, adatfeldolgozás, tárhelyszolgáltatás és kapcsolódó szolgáltatások | J10: 63 | K10: Számítástechnikai infrastruktúra, adatfeldolgozás, tárhelyszolgáltatás és egyéb információs szolgáltatási tevékenységek | L10: K | M10: TÁVKÖZLÉS, SZÁMÍTÓGÉPES PROGRAMOZÁS, INFORMÁCIÓTECHNOLÓGIAI SZAKTANÁCSADÁS, SZÁMÍTÁSTECHNIKAI INFRASTRUKTÚRA ÉS EGYÉB INFORMÁCIÓS SZOLGÁLTATÁSOK | N10: 113 | O10: Korlátolt felelősségű társaság | P10: 11 | Q10: Gazdasági társaság | R10: 1 | S10: Jogi személyiségű vállalkozás | T10: 13 | U10: Pest | V10: 12 | W10: Pest | X10: 1 | Y10: Közép-Magyarország | Z10: 2008 | AA10: 4 | AB10: 58040000 | AC10: 15 | AD10: 3-4 | AE10: 3 | AF10: 51 - 300 | AG10: 2006 - 2010 | AH10: mikrovállalkozás | AI10: 76 | AJ10: 76 | AK10: 76 | AL10: 76 | AM10: 76 | AN10: 76 | AO10: 76 | AP10: 76 | AQ10: 76 | AR10: 76 | AS10: 76 | AT10: 76 | AU10: 76 | AV10: 76 | AW10: 76 | AX10: 76 | AY10: 76 | AZ10: 76 | BA10: 76 | BB10: 76 | BC10: 76 | BD10: 76 | BE10: 76 | BF10: 76 | BG10: 76 | BH10: 76 | BI10: 76 | BJ10: 76 | BK10: 76 | BL10: 76 | BM10: 76 | BN10: 76 | BO10: 76 | BP10: 76 | BQ10: 76 | BR10: 76 | BS10: 76 | BT10: 76 | BU10: 76 | BV10: 76 | BW10: 76 | BX10: 76 | BY10: 1 | BZ10: 1 | CA10: 72.590909 | CB10: 76 | CC10: 15.803029 | CD10: 0.21769984 | CE10: 1 | CF10: 76 | CG10: 75 | CH10: -75 | CI10: 75
A11: 10 | B11: 6522 | C11: kiskegyed.hu | D11: 10237580-2-43 | E11: 10237580 5813 113 01 | F11: 58.13 | G11: Folyóirat, időszaki kiadvány kiadása | H11: 58.1 | I11: Könyv-, napilapkiadás, egyéb kiadói tevékenység (kivéve: szoftverkiadás) | J11: 58 | K11: Kiadói tevékenység | L11: J | M11: KIADÓI TEVÉKENYSÉG, MŰSORSZOLGÁLTATÁS, TARTALOMSZOLGÁLTATÁS ÉS -TERJESZTÉS | N11: 113 | O11: Korlátolt felelősségű társaság | P11: 11 | Q11: Gazdasági társaság | R11: 1 | S11: Jogi személyiségű vállalkozás | T11: 1 | U11: Budapest | V11: 11 | W11: Budapest | X11: 1 | Y11: Közép-Magyarország | Z11: 1989 | AA11: 283 | AB11: 12119080000 | AC11: 81 | AD11: 250-299 | AE11: C | AF11: 10001 - | AG11: 1986 - 1990 | AH11: nagyvállalat | AI11: 42 | AJ11: 42 | AK11: 42 | AL11: 42 | AM11: 42 | AN11: 44 | AO11: 44 | AP11: 43 | AQ11: 44 | AR11: 44 | AS11: 44 | AT11: 34 | AU11: 35 | AV11: 35 | AW11: 37 | AX11: 36 | AY11: 37 | AZ11: 37 | BA11: 36 | BB11: 36 | BC11: 36 | BD11: 37 | BE11: 37 | BF11: 33 | BG11: 33 | BH11: 34 | BI11: 34 | BJ11: 34 | BK11: 35 | BL11: 36 | BM11: 36 | BN11: 35 | BO11: 35 | BP11: 34 | BQ11: 35 | BR11: 35 | BS11: 37 | BT11: 36 | BU11: 37 | BV11: 38 | BW11: 36 | BX11: 37 | BY11: 33 | BZ11: 33 | CA11: 37.318182 | CB11: 36 | CC11: 3.5684191 | CD11: 0.095621463 | CE11: 33 | CF11: 44 | CG11: 11 | CH11: -9 | CI11: 9
A12: 11 | B12: 6536 | C12: telex.hu | D12: 32073380-2-41 | E12: 32073380 6039 114 01 | F12: 60.39 | G12: Egyéb tartalomterjesztési tevékenység | H12: 60.3 | I12: Hírügynökségi és egyéb tartalomterjesztési tevékenység | J12: 60 | K12: Műsor-összeállítás, műsorszolgáltatás, hírügynökségi és egyéb tartalomterjesztési tevékenység | L12: J | M12: KIADÓI TEVÉKENYSÉG, MŰSORSZOLGÁLTATÁS, TARTALOMSZOLGÁLTATÁS ÉS -TERJESZTÉS | N12: 114 | O12: Részvénytársaság | P12: 11 | Q12: Gazdasági társaság | R12: 1 | S12: Jogi személyiségű vállalkozás | T12: 1 | U12: Budapest | V12: 11 | W12: Budapest | X12: 1 | Y12: Közép-Magyarország | Z12: 2022 | AA12: 127 | AB12: 1115810000 | AC12: 61 | AD12: 100-149 | AE12: 7 | AF12: 1001 - 2500 | AG12: 2021 - 2025 | AH12: középvállalkozás | AI12: 203 | AJ12: 196 | AK12: 200 | AL12: 109 | AM12: 196 | AN12: 199 | AO12: 195 | AP12: 182 | AQ12: 188 | AR12: 193 | AS12: 206 | AT12: 205 | AU12: 209 | AV12: 208 | AW12: 187 | AX12: 192 | AY12: 197 | AZ12: 201 | BA12: 195 | BB12: 219 | BC12: 216 | BD12: 222 | BE12: 233 | BF12: 224 | BG12: 141 | BH12: 246 | BI12: 233 | BJ12: 125 | BK12: 240 | BL12: 235 | BM12: 131 | BN12: 131 | BO12: 127 | BP12: 132 | BQ12: 136 | BR12: 135 | BS12: 151 | BT12: 151 | BU12: 132 | BV12: 137 | BW12: 144 | BX12: 257 | BY12: 275 | BZ12: 269 | CA12: 188.70455 | CB12: 196 | CC12: 43.022211 | CD12: 0.22798715 | CE12: 109 | CF12: 275 | CG12: 166 | CH12: 66 | CI12: 66
A13: 12 | B13: 6565 | C13: tippmix.hu | D13: 10580204-2-44 | E13: 10580204 9200 114 01 | F13: 92 | G13: Szerencsejáték, fogadás | H13: 92 | I13: Szerencsejáték, fogadás | J13: 92 | K13: Szerencsejáték, fogadás | L13: S | M13: MŰVÉSZET, SPORT, SZABADIDŐ | N13: 114 | O13: Részvénytársaság | P13: 11 | Q13: Gazdasági társaság | R13: 1 | S13: Jogi személyiségű vállalkozás | T13: 1 | U13: Budapest | V13: 11 | W13: Budapest | X13: 1 | Y13: Közép-Magyarország | Z13: 1990 | AA13: 1910 | AB13: 1235816000000 | AC13: 93 | AD13: 1000-1999 | AE13: C | AF13: 10001 - | AG13: 1986 - 1990 | AH13: nagyvállalat | AI13: 620 | AJ13: 602 | AK13: 580 | AL13: 568 | AM13: 512 | AN13: 554 | AO13: 572 | AP13: 559 | AQ13: 518 | AR13: 539 | AS13: 612 | AT13: 588 | AU13: 587 | AV13: 606 | AW13: 579 | AX13: 588 | AY13: 607 | AZ13: 591 | BA13: 677 | BB13: 282 | BC13: 329 | BD13: 324 | BE13: 277 | BF13: 315 | BG13: 336 | BH13: 385 | BI13: 310 | BJ13: 288 | BK13: 348 | BL13: 275 | BM13: 332 | BN13: 314 | BO13: 299 | BP13: 318 | BQ13: 312 | BR13: 300 | BS13: 283 | BT13: 298 | BU13: 336 | BV13: 321 | BW13: 331 | BX13: 258 | BY13: 277 | BZ13: 308 | CA13: 427.61364 | CB13: 336 | CC13: 139.91779 | CD13: 0.32720609 | CE13: 258 | CF13: 677 | CG13: 419 | CH13: -312 | CI13: 312
A14: 13 | B14: 11330 | C14: nosalty.hu | D14: 25087910-2-41 | E14: 25087910 5813 114 01 | F14: 58.13 | G14: Folyóirat, időszaki kiadvány kiadása | H14: 58.1 | I14: Könyv-, napilapkiadás, egyéb kiadói tevékenység (kivéve: szoftverkiadás) | J14: 58 | K14: Kiadói tevékenység | L14: J | M14: KIADÓI TEVÉKENYSÉG, MŰSORSZOLGÁLTATÁS, TARTALOMSZOLGÁLTATÁS ÉS -TERJESZTÉS | N14: 114 | O14: Részvénytársaság | P14: 11 | Q14: Gazdasági társaság | R14: 1 | S14: Jogi személyiségű vállalkozás | T14: 1 | U14: Budapest | V14: 11 | W14: Budapest | X14: 1 | Y14: Közép-Magyarország | Z14: 2014 | AA14: 409 | AB14: 14254790000 | AC14: 82 | AD14: 300-499 | AE14: C | AF14: 10001 - | AG14: 2011 - 2015 | AH14: nagyvállalat | AI14: 74 | AJ14: 74 | AK14: 74 | AL14: 74 | AM14: 73 | AN14: 73 | AO14: 73 | AP14: 73 | AQ14: 73 | AR14: 80 | AS14: 80 | AT14: 82 | AU14: 79 | AV14: 69 | AW14: 69 | AX14: 75 | AY14: 75 | AZ14: 75 | BA14: 72 | BB14: 75 | BC14: 75 | BD14: 75 | BE14: 74 | BF14: 75 | BG14: 70 | BH14: 73 | BI14: 68 | BJ14: 68 | BK14: 69 | BL14: 79 | BM14: 78 | BN14: 77 | BO14: 77 | BP14: 78 | BQ14: 78 | BR14: 66 | BS14: 76 | BT14: 75 | BU14: 72 | BV14: 70 | BW14: 65 | BX14: 69 | BY14: 69 | BZ14: 69 | CA14: 73.568182 | CB14: 74 | CC14: 3.9437777 | CD14: 0.053607111 | CE14: 65 | CF14: 82 | CG14: 17 | CH14: -5 | CI14: 5
A15: 14 | B15: 11465 | C15: origo.hu | D15: 24785725-2-44 | E15: 24785725 5812 114 01 | F15: 58.12 | G15: Napilapkiadás | H15: 58.1 | I15: Könyv-, napilapkiadás, egyéb kiadói tevékenység (kivéve: szoftverkiadás) | J15: 58 | K15: Kiadói tevékenység | L15: J | M15: KIADÓI TEVÉKENYSÉG, MŰSORSZOLGÁLTATÁS, TARTALOMSZOLGÁLTATÁS ÉS -TERJESZTÉS | N15: 114 | O15: Részvénytársaság | P15: 11 | Q15: Gazdasági társaság | R15: 1 | S15: Jogi személyiségű vállalkozás | T15: 1 | U15: Budapest | V15: 11 | W15: Budapest | X15: 1 | Y15: Közép-Magyarország | Z15: 2013 | AA15: 1974 | AB15: 57098150000 | AC15: 93 | AD15: 1000-1999 | AE15: C | AF15: 10001 - | AG15: 2011 - 2015 | AH15: nagyvállalat | AI15: 30 | AJ15: 36 | AK15: 36 | AL15: 31 | AM15: 37 | AN15: 35 | AO15: 33 | AP15: 30 | AQ15: 28 | AR15: 31 | AS15: 32 | AT15: 26 | AU15: 29 | AV15: 27 | AW15: 33 | AX15: 30 | AY15: 30 | AZ15: 30 | BA15: 31 | BB15: 33 | BC15: 31 | BD15: 34 | BE15: 31 | BF15: 34 | BG15: 26 | BH15: 32 | BI15: 35 | BJ15: 32 | BK15: 37 | BL15: 36 | BM15: 34 | BN15: 37 | BO15: 33 | BP15: 35 | BQ15: 34 | BR15: 34 | BS15: 36 | BT15: 33 | BU15: 33 | BV15: 36 | BW15: 35 | BX15: 35 | BY15: 39 | BZ15: 36 | CA15: 32.863636 | CB15: 33 | CC15: 3.0696633 | CD15: 0.093406077 | CE15: 26 | CF15: 39 | CG15: 13 | CH15: 6 | CI15: 6
A16: 15 | B16: 11839 | C16: atw.hu | D16: 13471868-2-41 | E16: 13471868 6220 113 01 | F16: 62.2 | G16: Információtechnológiai szaktanácsadás és számítástechnikai eszközök, rendszerek üzemeltetése | H16: 62.2 | I16: Információtechnológiai szaktanácsadás és számítástechnikai eszközök, rendszerek üzemeltetése | J16: 62 | K16: Információtechnológiai szolgáltatás | L16: K | M16: TÁVKÖZLÉS, SZÁMÍTÓGÉPES PROGRAMOZÁS, INFORMÁCIÓTECHNOLÓGIAI SZAKTANÁCSADÁS, SZÁMÍTÁSTECHNIKAI INFRASTRUKTÚRA ÉS EGYÉB INFORMÁCIÓS SZOLGÁLTATÁSOK | N16: 113 | O16: Korlátolt felelősségű társaság | P16: 11 | Q16: Gazdasági társaság | R16: 1 | S16: Jogi személyiségű vállalkozás | T16: 1 | U16: Budapest | V16: 11 | W16: Budapest | X16: 1 | Y16: Közép-Magyarország | Z16: 2005 | AA16: 8 | AB16: 374800000 | AC16: 22 | AD16: 5-9 | AE16: 4 | AF16: 301 - 500 | AG16: 2001 - 2005 | AH16: mikrovállalkozás | AI16: 43 | AJ16: 43 | AK16: 43 | AL16: 44 | AM16: 45 | AN16: 45 | AO16: 45 | AP16: 45 | AQ16: 45 | AR16: 45 | AS16: 45 | AT16: 45 | AU16: 45 | AV16: 45 | AW16: 45 | AX16: 45 | AY16: 45 | AZ16: 45 | BA16: 45 | BB16: 45 | BC16: 45 | BD16: 45 | BE16: 45 | BF16: 45 | BG16: 45 | BH16: 45 | BI16: 45 | BJ16: 45 | BK16: 44 | BL16: 44 | BM16: 44 | BN16: 44 | BO16: 44 | BP16: 44 | BQ16: 44 | BR16: 44 | BS16: 44 | BT16: 44 | BU16: 44 | BV16: 44 | BW16: 44 | BX16: 44 | BY16: 44 | BZ16: 44 | CA16: 44.477273 | CB16: 45 | CC16: 0.62834727 | CD16: 0.014127379 | CE16: 43 | CF16: 45 | CG16: 2 | CH16: 1 | CI16: 1
A17: 16 | B17: 12384 | C17: elte.hu | D17: 15308744-2-41 | E17: 15308744 8540 312 01 | F17: 85.4 | G17: Felsőoktatás | H17: 85.4 | I17: Felsőoktatás | J17: 85 | K17: Oktatás | L17: Q | M17: OKTATÁS | N17: 312 | O17: Központi költségvetési szerv | P17: 31 | Q17: Központi költségvetési irányító és költségvetési szervek | R17: 3 | S17: Költségvetési szervek és költségvetési rend szerint gazdálkodó szervek | T17: 1 | U17: Budapest | V17: 11 | W17: Budapest | X17: 1 | Y17: Közép-Magyarország | Z17: 1983 | AA17: 4351 | AC17: 94 | AD17: 2000-4999 | AE17: 0 | AF17: ismeretlen | AG17: - 1985 | AI17: 29 | AJ17: 29 | AK17: 29 | AL17: 31 | AM17: 31 | AN17: 31 | AO17: 30 | AP17: 30 | AQ17: 30 | AR17: 31 | AS17: 31 | AT17: 31 | AU17: 31 | AV17: 31 | AW17: 31 | AX17: 31 | AY17: 31 | AZ17: 30 | BA17: 31 | BB17: 30 | BC17: 30 | BD17: 33 | BE17: 33 | BF17: 33 | BG17: 33 | BH17: 32 | BI17: 31 | BJ17: 31 | BK17: 32 | BL17: 32 | BM17: 32 | BN17: 32 | BO17: 31 | BP17: 31 | BQ17: 30 | BR17: 29 | BS17: 29 | BT17: 29 | BU17: 29 | BV17: 29 | BW17: 20 | BX17: 18 | BY17: 18 | BZ17: 20 | CA17: 29.681818 | CB17: 31 | CC17: 3.6201807 | CD17: 0.12196627 | CE17: 18 | CF17: 33 | CG17: 15 | CH17: -9 | CI17: 9
A18: 17 | B18: 12423 | C18: arukereso.hu | D18: 24868291-2-42 | E18: 24868291 6391 113 01 | F18: 63.91 | G18: Internetes keresőportállal kapcsolatos tevékenységek | H18: 63.9 | I18: Internetes keresőportállal kapcsolatos tevékenységek és egyéb információs szolgáltatás | J18: 63 | K18: Számítástechnikai infrastruktúra, adatfeldolgozás, tárhelyszolgáltatás és egyéb információs szolgáltatási tevékenységek | L18: K | M18: TÁVKÖZLÉS, SZÁMÍTÓGÉPES PROGRAMOZÁS, INFORMÁCIÓTECHNOLÓGIAI SZAKTANÁCSADÁS, SZÁMÍTÁSTECHNIKAI INFRASTRUKTÚRA ÉS EGYÉB INFORMÁCIÓS SZOLGÁLTATÁSOK | N18: 113 | O18: Korlátolt felelősségű társaság | P18: 11 | Q18: Gazdasági társaság | R18: 1 | S18: Jogi személyiségű vállalkozás | T18: 1 | U18: Budapest | V18: 11 | W18: Budapest | X18: 1 | Y18: Közép-Magyarország | Z18: 2014 | AA18: 106 | AB18: 9502310000 | AC18: 61 | AD18: 100-149 | AE18: B | AF18: 7001 - 10000 | AG18: 2011 - 2015 | AH18: középvállalkozás | AI18: 36 | AJ18: 35 | AK18: 35 | AL18: 36 | AM18: 34 | AN18: 34 | AO18: 34 | AP18: 31 | AQ18: 31 | AR18: 31 | AS18: 31 | AT18: 31 | AU18: 31 | AV18: 31 | AW18: 31 | AX18: 31 | AY18: 31 | AZ18: 31 | BA18: 28 | BB18: 26 | BC18: 26 | BD18: 26 | BE18: 27 | BF18: 27 | BG18: 27 | BH18: 28 | BI18: 27 | BJ18: 27 | BK18: 28 | BL18: 27 | BM18: 28 | BN18: 28 | BO18: 27 | BP18: 28 | BQ18: 28 | BR18: 31 | BS18: 31 | BT18: 28 | BU18: 28 | BV18: 28 | BW18: 30 | BX18: 29 | BY18: 29 | BZ18: 28 | CA18: 29.772727 | CB18: 29 | CC18: 2.8025208 | CD18: 0.094130468 | CE18: 26 | CF18: 36 | CG18: 10 | CH18: -8 | CI18: 8
A19: 18 | B19: 12797 | C19: blikk.hu | D19: 10237580-2-43 | E19: 10237580 5813 113 01 | F19: 58.13 | G19: Folyóirat, időszaki kiadvány kiadása | H19: 58.1 | I19: Könyv-, napilapkiadás, egyéb kiadói tevékenység (kivéve: szoftverkiadás) | J19: 58 | K19: Kiadói tevékenység | L19: J | M19: KIADÓI TEVÉKENYSÉG, MŰSORSZOLGÁLTATÁS, TARTALOMSZOLGÁLTATÁS ÉS -TERJESZTÉS | N19: 113 | O19: Korlátolt felelősségű társaság | P19: 11 | Q19: Gazdasági társaság | R19: 1 | S19: Jogi személyiségű vállalkozás | T19: 1 | U19: Budapest | V19: 11 | W19: Budapest | X19: 1 | Y19: Közép-Magyarország | Z19: 1989 | AA19: 283 | AB19: 12119080000 | AC19: 81 | AD19: 250-299 | AE19: C | AF19: 10001 - | AG19: 1986 - 1990 | AH19: nagyvállalat | AI19: 13 | AJ19: 13 | AK19: 30 | AL19: 15 | AM19: 11 | AN19: 21 | AO19: 34 | AP19: 26 | AQ19: 26 | AR19: 26 | AS19: 24 | AT19: 37 | AU19: 24 | AV19: 24 | AW19: 24 | AX19: 24 | AY19: 24 | AZ19: 24 | BA19: 10 | BB19: 38 | BC19: 26 | BD19: 26 | BE19: 26 | BF19: 24 | BG19: 28 | BH19: 24 | BI19: 24 | BJ19: 30 | BK19: 26 | BL19: 26 | BM19: 30 | BN19: 15 | BO19: 31 | BP19: 15 | BQ19: 23 | BR19: 32 | BS19: 35 | BT19: 36 | BU19: 35 | BV19: 36 | BW19: 34 | BX19: 27 | BY19: 29 | BZ19: 27 | CA19: 25.75 | CB19: 26 | CC19: 7.0418186 | CD19: 0.27346868 | CE19: 10 | CF19: 38 | CG19: 28 | CH19: 14 | CI19: 14
A20: 19 | B20: 12873 | C20: freemail.hu | D20: 24785725-2-44 | E20: 24785725 5812 114 01 | F20: 58.12 | G20: Napilapkiadás | H20: 58.1 | I20: Könyv-, napilapkiadás, egyéb kiadói tevékenység (kivéve: szoftverkiadás) | J20: 58 | K20: Kiadói tevékenység | L20: J | M20: KIADÓI TEVÉKENYSÉG, MŰSORSZOLGÁLTATÁS, TARTALOMSZOLGÁLTATÁS ÉS -TERJESZTÉS | N20: 114 | O20: Részvénytársaság | P20: 11 | Q20: Gazdasági társaság | R20: 1 | S20: Jogi személyiségű vállalkozás | T20: 1 | U20: Budapest | V20: 11 | W20: Budapest | X20: 1 | Y20: Közép-Magyarország | Z20: 2013 | AA20: 1974 | AB20: 57098150000 | AC20: 93 | AD20: 1000-1999 | AE20: C | AF20: 10001 - | AG20: 2011 - 2015 | AH20: nagyvállalat | AI20: 48 | AJ20: 48 | AK20: 46 | AL20: 46 | AM20: 46 | AN20: 46 | AO20: 49 | AP20: 42 | AQ20: 42 | AR20: 44 | AS20: 42 | AT20: 44 | AU20: 44 | AV20: 44 | AW20: 42 | AX20: 14 | AY20: 42 | AZ20: 44 | BA20: 44 | BB20: 44 | BC20: 44 | BD20: 44 | BE20: 42 | BF20: 42 | BG20: 46 | BH20: 42 | BI20: 45 | BJ20: 35 | BK20: 33 | BL20: 33 | BM20: 33 | BN20: 33 | BO20: 33 | BP20: 33 | BQ20: 35 | BR20: 35 | BS20: 35 | BT20: 32 | BU20: 31 | BV20: 32 | BW20: 32 | BX20: 32 | BY20: 32 | BZ20: 32 | CA20: 39.25 | CB20: 42 | CC20: 6.9887784 | CD20: 0.17805805 | CE20: 14 | CF20: 49 | CG20: 35 | CH20: -16 | CI20: 16
A21: 20 | B21: 12951 | C21: nemzetisport.hu | D21: 32048467-2-51 | E21: 32048467 5812 113 01 | F21: 58.12 | G21: Napilapkiadás | H21: 58.1 | I21: Könyv-, napilapkiadás, egyéb kiadói tevékenység (kivéve: szoftverkiadás) | J21: 58 | K21: Kiadói tevékenység | L21: J | M21: KIADÓI TEVÉKENYSÉG, MŰSORSZOLGÁLTATÁS, TARTALOMSZOLGÁLTATÁS ÉS -TERJESZTÉS | N21: 113 | O21: Korlátolt felelősségű társaság | P21: 11 | Q21: Gazdasági társaság | R21: 1 | S21: Jogi személyiségű vállalkozás | T21: 1 | U21: Budapest | V21: 11 | W21: Budapest | X21: 1 | Y21: Közép-Magyarország | Z21: 2022 | AA21: 113 | AB21: 1983290000 | AC21: 61 | AD21: 100-149 | AE21: 7 | AF21: 1001 - 2500 | AG21: 2021 - 2025 | AH21: középvállalkozás | AI21: 92 | AJ21: 92 | AK21: 93 | AL21: 96 | AM21: 98 | AN21: 103 | AO21: 93 | AP21: 100 | AQ21: 99 | AR21: 97 | AS21: 95 | AT21: 93 | AU21: 91 | AV21: 84 | AW21: 88 | AX21: 88 | AY21: 91 | AZ21: 86 | BA21: 89 | BB21: 89 | BC21: 82 | BD21: 88 | BE21: 85 | BF21: 87 | BG21: 86 | BH21: 81 | BI21: 88 | BJ21: 158 | BK21: 97 | BL21: 90 | BM21: 90 | BN21: 86 | BO21: 87 | BP21: 90 | BQ21: 86 | BR21: 89 | BS21: 86 | BT21: 89 | BU21: 88 | BV21: 88 | BW21: 84 | BX21: 87 | BY21: 85 | BZ21: 86 | CA21: 91.363636 | CB21: 89 | CC21: 11.381525 | CD21: 0.12457391 | CE21: 81 | CF21: 158 | CG21: 77 | CH21: -6 | CI21: 6
A22: 21 | B22: 13229 | C22: 444.hu | D22: 24298083-2-42 | E22: 24298083 6039 114 01 | F22: 60.39 | G22: Egyéb tartalomterjesztési tevékenység | H22: 60.3 | I22: Hírügynökségi és egyéb tartalomterjesztési tevékenység | J22: 60 | K22: Műsor-összeállítás, műsorszolgáltatás, hírügynökségi és egyéb tartalomterjesztési tevékenység | L22: J | M22: KIADÓI TEVÉKENYSÉG, MŰSORSZOLGÁLTATÁS, TARTALOMSZOLGÁLTATÁS ÉS -TERJESZTÉS | N22: 114 | O22: Részvénytársaság | P22: 11 | Q22: Gazdasági társaság | R22: 1 | S22: Jogi személyiségű vállalkozás | T22: 1 | U22: Budapest | V22: 11 | W22: Budapest | X22: 1 | Y22: Közép-Magyarország | Z22: 2013 | AA22: 84 | AB22: 1137110000 | AC22: 50 | AD22: 50-99 | AE22: 7 | AF22: 1001 - 2500 | AG22: 2011 - 2015 | AH22: középvállalkozás | AI22: 35 | AJ22: 4 | AK22: 4 | AL22: 4 | AM22: 4 | AN22: 4 | AO22: 4 | AP22: 4 | AQ22: 4 | AR22: 4 | AS22: 4 | AT22: 4 | AU22: 4 | AV22: 4 | AW22: 4 | AX22: 4 | AY22: 4 | AZ22: 4 | BA22: 4 | BB22: 4 | BC22: 4 | BD22: 4 | BE22: 4 | BF22: 4 | BG22: 4 | BH22: 4 | BI22: 4 | BJ22: 4 | BK22: 4 | BL22: 4 | BM22: 4 | BN22: 4 | BO22: 4 | BP22: 4 | BQ22: 4 | BR22: 4 | BS22: 4 | BT22: 4 | BU22: 4 | BV22: 4 | BW22: 4 | BX22: 4 | BY22: 4 | BZ22: 4 | CA22: 4.7045455 | CB22: 4 | CC22: 4.6734258 | CD22: 0.9933852 | CE22: 4 | CF22: 35 | CG22: 31 | CH22: -31 | CI22: 31
A23: 22 | B23: 13615 | C23: startlap.hu | D23: 25087910-2-41 | E23: 25087910 5813 114 01 | F23: 58.13 | G23: Folyóirat, időszaki kiadvány kiadása | H23: 58.1 | I23: Könyv-, napilapkiadás, egyéb kiadói tevékenység (kivéve: szoftverkiadás) | J23: 58 | K23: Kiadói tevékenység | L23: J | M23: KIADÓI TEVÉKENYSÉG, MŰSORSZOLGÁLTATÁS, TARTALOMSZOLGÁLTATÁS ÉS -TERJESZTÉS | N23: 114 | O23: Részvénytársaság | P23: 11 | Q23: Gazdasági társaság | R23: 1 | S23: Jogi személyiségű vállalkozás | T23: 1 | U23: Budapest | V23: 11 | W23: Budapest | X23: 1 | Y23: Közép-Magyarország | Z23: 2014 | AA23: 409 | AB23: 14254790000 | AC23: 82 | AD23: 300-499 | AE23: C | AF23: 10001 - | AG23: 2011 - 2015 | AH23: nagyvállalat | AI23: 247 | AJ23: 247 | AK23: 245 | AL23: 244 | AM23: 247 | AN23: 244 | AO23: 247 | AP23: 244 | AQ23: 245 | AR23: 249 | AS23: 247 | AT23: 247 | AU23: 244 | AV23: 248 | AW23: 243 | AX23: 246 | AY23: 244 | AZ23: 247 | BA23: 224 | BB23: 245 | BC23: 241 | BD23: 242 | BE23: 249 | BF23: 245 | BG23: 246 | BH23: 246 | BI23: 241 | BJ23: 247 | BK23: 255 | BL23: 253 | BM23: 253 | BN23: 244 | BO23: 243 | BP23: 250 | BQ23: 243 | BR23: 248 | BS23: 248 | BT23: 246 | BU23: 250 | BV23: 245 | BW23: 246 | BX23: 247 | BY23: 257 | BZ23: 255 | CA23: 246.22727 | CB23: 246 | CC23: 4.954977 | CD23: 0.020123591 | CE23: 224 | CF23: 257 | CG23: 33 | CH23: 8 | CI23: 8
A24: 23 | B24: 13876 | C24: mindmegette.hu | D24: 24785725-2-44 | E24: 24785725 5812 114 01 | F24: 58.12 | G24: Napilapkiadás | H24: 58.1 | I24: Könyv-, napilapkiadás, egyéb kiadói tevékenység (kivéve: szoftverkiadás) | J24: 58 | K24: Kiadói tevékenység | L24: J | M24: KIADÓI TEVÉKENYSÉG, MŰSORSZOLGÁLTATÁS, TARTALOMSZOLGÁLTATÁS ÉS -TERJESZTÉS | N24: 114 | O24: Részvénytársaság | P24: 11 | Q24: Gazdasági társaság | R24: 1 | S24: Jogi személyiségű vállalkozás | T24: 1 | U24: Budapest | V24: 11 | W24: Budapest | X24: 1 | Y24: Közép-Magyarország | Z24: 2013 | AA24: 1974 | AB24: 57098150000 | AC24: 93 | AD24: 1000-1999 | AE24: C | AF24: 10001 - | AG24: 2011 - 2015 | AH24: nagyvállalat | AI24: 244 | AJ24: 226 | AK24: 228 | AL24: 188 | AM24: 185 | AN24: 185 | AO24: 185 | AP24: 184 | AQ24: 185 | AR24: 163 | AS24: 163 | AT24: 160 | AU24: 161 | AV24: 160 | AW24: 162 | AX24: 161 | AY24: 161 | AZ24: 162 | BA24: 162 | BB24: 161 | BC24: 163 | BD24: 163 | BE24: 163 | BF24: 165 | BG24: 164 | BH24: 164 | BI24: 168 | BJ24: 160 | BK24: 207 | BL24: 187 | BM24: 160 | BN24: 159 | BO24: 156 | BP24: 158 | BQ24: 158 | BR24: 158 | BS24: 153 | BT24: 157 | BU24: 159 | BV24: 164 | BW24: 163 | BX24: 174 | BY24: 203 | BZ24: 206 | CA24: 173.13636 | CB24: 163 | CC24: 21.402663 | CD24: 0.12361738 | CE24: 153 | CF24: 244 | CG24: 91 | CH24: -38 | CI24: 38
A25: 24 | B25: 13880 | C25: index.hu | D25: 12765335-2-41 | E25: 12765335 5812 114 01 | F25: 58.12 | G25: Napilapkiadás | H25: 58.1 | I25: Könyv-, napilapkiadás, egyéb kiadói tevékenység (kivéve: szoftverkiadás) | J25: 58 | K25: Kiadói tevékenység | L25: J | M25: KIADÓI TEVÉKENYSÉG, MŰSORSZOLGÁLTATÁS, TARTALOMSZOLGÁLTATÁS ÉS -TERJESZTÉS | N25: 114 | O25: Részvénytársaság | P25: 11 | Q25: Gazdasági társaság | R25: 1 | S25: Jogi személyiségű vállalkozás | T25: 1 | U25: Budapest | V25: 11 | W25: Budapest | X25: 1 | Y25: Közép-Magyarország | Z25: 2001 | AA25: 77 | AB25: 1911720000 | AC25: 50 | AD25: 50-99 | AE25: 7 | AF25: 1001 - 2500 | AG25: 2001 - 2005 | AH25: középvállalkozás | AI25: 210 | AJ25: 216 | AK25: 212 | AL25: 207 | AM25: 211 | AN25: 218 | AO25: 209 | AP25: 199 | AQ25: 195 | AR25: 207 | AS25: 204 | AT25: 208 | AU25: 201 | AV25: 198 | AW25: 206 | AX25: 204 | AY25: 201 | AZ25: 209 | BA25: 193 | BB25: 206 | BC25: 228 | BD25: 214 | BE25: 210 | BF25: 214 | BG25: 207 | BH25: 205 | BI25: 204 | BJ25: 205 | BK25: 211 | BL25: 221 | BM25: 210 | BN25: 213 | BO25: 227 | BP25: 227 | BQ25: 222 | BR25: 228 | BS25: 224 | BT25: 234 | BU25: 224 | BV25: 222 | BW25: 217 | BX25: 227 | BY25: 225 | BZ25: 230 | CA25: 212.79545 | CB25: 210.5 | CC25: 10.267536 | CD25: 0.048250732 | CE25: 193 | CF25: 234 | CG25: 41 | CH25: 20 | CI25: 20
A26: 25 | B26: 13955 | C26: penzcentrum.hu | D26: 12527052-2-41 | E26: 12527052 6039 114 01 | F26: 60.39 | G26: Egyéb tartalomterjesztési tevékenység | H26: 60.3 | I26: Hírügynökségi és egyéb tartalomterjesztési tevékenység | J26: 60 | K26: Műsor-összeállítás, műsorszolgáltatás, hírügynökségi és egyéb tartalomterjesztési tevékenység | L26: J | M26: KIADÓI TEVÉKENYSÉG, MŰSORSZOLGÁLTATÁS, TARTALOMSZOLGÁLTATÁS ÉS -TERJESZTÉS | N26: 114 | O26: Részvénytársaság | P26: 11 | Q26: Gazdasági társaság | R26: 1 | S26: Jogi személyiségű vállalkozás | T26: 1 | U26: Budapest | V26: 11 | W26: Budapest | X26: 1 | Y26: Közép-Magyarország | Z26: 2000 | AA26: 89 | AB26: 4394160000 | AC26: 50 | AD26: 50-99 | AE26: A | AF26: 4001 - 7000 | AG26: 1996 - 2000 | AH26: középvállalkozás | AI26: 152 | AJ26: 148 | AK26: 149 | AL26: 148 | AM26: 145 | AN26: 150 | AO26: 150 | AP26: 146 | AQ26: 147 | AR26: 149 | AS26: 152 | AT26: 153 | AU26: 192 | AV26: 193 | AW26: 188 | AX26: 189 | AY26: 190 | AZ26: 199 | BA26: 183 | BB26: 184 | BC26: 247 | BD26: 276 | BE26: 245 | BF26: 279 | BG26: 212 | BH26: 250 | BI26: 283 | BJ26: 255 | BK26: 282 | BL26: 250 | BM26: 212 | BN26: 233 | BO26: 228 | BP26: 237 | BQ26: 273 | BR26: 270 | BS26: 245 | BT26: 248 | BU26: 274 | BV26: 280 | BW26: 249 | BX26: 273 | BY26: 273 | BZ26: 206 | CA26: 213.34091 | CB26: 212 | CC26: 49.48993 | CD26: 0.23197581 | CE26: 145 | CF26: 283 | CG26: 138 | CH26: 54 | CI26: 54
A27: 26 | B27: 14075 | C27: port.hu | D27: 27936748-2-41 | E27: 27936748 6391 113 01 | F27: 63.91 | G27: Internetes keresőportállal kapcsolatos tevékenységek | H27: 63.9 | I27: Internetes keresőportállal kapcsolatos tevékenységek és egyéb információs szolgáltatás | J27: 63 | K27: Számítástechnikai infrastruktúra, adatfeldolgozás, tárhelyszolgáltatás és egyéb információs szolgáltatási tevékenységek | L27: K | M27: TÁVKÖZLÉS, SZÁMÍTÓGÉPES PROGRAMOZÁS, INFORMÁCIÓTECHNOLÓGIAI SZAKTANÁCSADÁS, SZÁMÍTÁSTECHNIKAI INFRASTRUKTÚRA ÉS EGYÉB INFORMÁCIÓS SZOLGÁLTATÁSOK | N27: 113 | O27: Korlátolt felelősségű társaság | P27: 11 | Q27: Gazdasági társaság | R27: 1 | S27: Jogi személyiségű vállalkozás | T27: 1 | U27: Budapest | V27: 11 | W27: Budapest | X27: 1 | Y27: Közép-Magyarország | Z27: 2020 | AA27: 65 | AB27: 196970000 | AC27: 50 | AD27: 50-99 | AE27: 3 | AF27: 51 - 300 | AG27: 2016 - 2020 | AH27: középvállalkozás | AI27: 413 | AJ27: 436 | AK27: 432 | AL27: 425 | AM27: 458 | AN27: 399 | AO27: 405 | AP27: 400 | AQ27: 417 | AR27: 401 | AS27: 434 | AT27: 459 | AU27: 409 | AV27: 409 | AW27: 495 | AX27: 442 | AY27: 440 | AZ27: 467 | BA27: 302 | BB27: 436 | BC27: 463 | BD27: 433 | BE27: 455 | BF27: 447 | BG27: 452 | BH27: 458 | BI27: 423 | BJ27: 423 | BK27: 431 | BL27: 394 | BM27: 434 | BN27: 395 | BO27: 429 | BP27: 421 | BQ27: 431 | BR27: 426 | BS27: 462 | BT27: 435 | BU27: 442 | BV27: 430 | BW27: 438 | BX27: 440 | BY27: 449 | BZ27: 442 | CA27: 430.27273 | CB27: 433.5 | CC27: 29.136698 | CD27: 0.067716812 | CE27: 302 | CF27: 495 | CG27: 193 | CH27: 29 | CI27: 29
A28: 27 | B28: 14476 | C28: promotions.hu | D28: 23749122-2-15 | E28: 23749122 7311 113 15 | F28: 73.11 | G28: Reklámügynöki tevékenység | H28: 73.1 | I28: Reklám | J28: 73 | K28: Reklám, piackutatás, PR-tevékenység | L28: N | M28: SZAKMAI, TUDOMÁNYOS, MŰSZAKI TEVÉKENYSÉG | N28: 113 | O28: Korlátolt felelősségű társaság | P28: 11 | Q28: Gazdasági társaság | R28: 1 | S28: Jogi személyiségű vállalkozás | T28: 15 | U28: Szabolcs-Szatmár-Bereg | V28: 60 | W28: Észak-Alföld | X28: 3 | Y28: Alföld és Észak | Z28: 2011 | AA28: 2 | AB28: 131750000 | AC28: 12 | AD28: 2 | AE28: 3 | AF28: 51 - 300 | AG28: 2011 - 2015 | AH28: mikrovállalkozás | AI28: 55 | AJ28: 50 | AK28: 53 | AL28: 57 | AM28: 49 | AN28: 51 | AO28: 54 | AP28: 57 | AQ28: 55 | AR28: 63 | AS28: 59 | AT28: 61 | AU28: 67 | AV28: 64 | AW28: 59 | AX28: 58 | AY28: 62 | AZ28: 65 | BA28: 58 | BB28: 60 | BC28: 64 | BD28: 68 | BE28: 63 | BF28: 71 | BG28: 68 | BH28: 81 | BI28: 59 | BJ28: 70 | BK28: 67 | BL28: 72 | BM28: 61 | BN28: 55 | BO28: 61 | BP28: 83 | BQ28: 82 | BR28: 66 | BS28: 77 | BT28: 68 | BU28: 68 | BV28: 74 | BW28: 72 | BX28: 72 | BY28: 81 | BZ28: 73 | CA28: 64.386364 | CB28: 63.5 | CC28: 8.7848069 | CD28: 0.13643894 | CE28: 49 | CF28: 83 | CG28: 34 | CH28: 18 | CI28: 18
A29: 28 | B29: 14563 | C29: szamlazz.hu | D29: 13421739-2-41 | E29: 13421739 6210 113 01 | F29: 62.1 | G29: Számítógépes programozás | H29: 62.1 | I29: Számítógépes programozás | J29: 62 | K29: Információtechnológiai szolgáltatás | L29: K | M29: TÁVKÖZLÉS, SZÁMÍTÓGÉPES PROGRAMOZÁS, INFORMÁCIÓTECHNOLÓGIAI SZAKTANÁCSADÁS, SZÁMÍTÁSTECHNIKAI INFRASTRUKTÚRA ÉS EGYÉB INFORMÁCIÓS SZOLGÁLTATÁSOK | N29: 113 | O29: Korlátolt felelősségű társaság | P29: 11 | Q29: Gazdasági társaság | R29: 1 | S29: Jogi személyiségű vállalkozás | T29: 1 | U29: Budapest | V29: 11 | W29: Budapest | X29: 1 | Y29: Közép-Magyarország | Z29: 2004 | AA29: 69 | AB29: 5227240000 | AC29: 50 | AD29: 50-99 | AE29: A | AF29: 4001 - 7000 | AG29: 2001 - 2005 | AH29: középvállalkozás | AI29: 106 | AJ29: 106 | AK29: 106 | AL29: 106 | AM29: 106 | AN29: 106 | AO29: 106 | AP29: 106 | AQ29: 106 | AR29: 106 | AS29: 106 | AT29: 106 | AU29: 106 | AV29: 106 | AW29: 106 | AX29: 106 | AY29: 106 | AZ29: 106 | BA29: 106 | BB29: 64 | BC29: 64 | BD29: 64 | BE29: 64 | BF29: 64 | BG29: 64 | BH29: 64 | BI29: 64 | BJ29: 64 | BK29: 64 | BL29: 64 | BM29: 64 | BN29: 64 | BO29: 64 | BP29: 64 | BQ29: 64 | BR29: 64 | BS29: 64 | BT29: 64 | BU29: 64 | BV29: 64 | BW29: 64 | BX29: 64 | BY29: 64 | BZ29: 64 | CA29: 82.136364 | CB29: 64 | CC29: 21.044351 | CD29: 0.25621235 | CE29: 64 | CF29: 106 | CG29: 42 | CH29: -42 | CI29: 42
... A34: 33 | B34: 15618 | C34: femina.hu | D34: 27936748-2-41 | E34: 27936748 6391 113 01 | F34: 63.91 | G34: Internetes keresőportállal kapcsolatos tevékenységek | H34: 63.9 | I34: Internetes keresőportállal kapcsolatos tevékenységek és egyéb információs szolgáltatás | J34: 63 | K34: Számítástechnikai infrastruktúra, adatfeldolgozás, tárhelyszolgáltatás és egyéb információs szolgáltatási tevékenységek | L34: K | M34: TÁVKÖZLÉS, SZÁMÍTÓGÉPES PROGRAMOZÁS, INFORMÁCIÓTECHNOLÓGIAI SZAKTANÁCSADÁS, SZÁMÍTÁSTECHNIKAI INFRASTRUKTÚRA ÉS EGYÉB INFORMÁCIÓS SZOLGÁLTATÁSOK | N34: 113 | O34: Korlátolt felelősségű társaság | P34: 11 | Q34: Gazdasági társaság | R34: 1 | S34: Jogi személyiségű vállalkozás | T34: 1 | U34: Budapest | V34: 11 | W34: Budapest | X34: 1 | Y34: Közép-Magyarország | Z34: 2020 | AA34: 65 | AB34: 196970000 | AC34: 50 | AD34: 50-99 | AE34: 3 | AF34: 51 - 300 | AG34: 2016 - 2020 | AH34: középvállalkozás | AI34: 75 | AJ34: 77 | AK34: 79 | AL34: 75 | AM34: 79 | AN34: 77 | AO34: 82 | AP34: 77 | AQ34: 80 | AR34: 77 | AS34: 77 | AT34: 76 | AU34: 79 | AV34: 74 | AW34: 78 | AX34: 80 | AY34: 75 | AZ34: 76 | BA34: 74 | BB34: 75 | BC34: 77 | BD34: 74 | BE34: 73 | BF34: 73 | BG34: 75 | BH34: 83 | BI34: 75 | BJ34: 75 | BK34: 79 | BL34: 78 | BM34: 74 | BN34: 76 | BO34: 77 | BP34: 72 | BQ34: 73 | BR34: 72 | BS34: 66 | BT34: 73 | BU34: 67 | BV34: 74 | BW34: 77 | BX34: 75 | BY34: 69 | BZ34: 75 | CA34: 75.545455 | CB34: 75 | CC34: 3.365036 | CD34: 0.044543196 | CE34: 66 | CF34: 83 | CG34: 17 | CH34: 0 | CI34: 0
A35: 34 | B35: 16336 | C35: bme.hu | D35: 19410768-4-43 | E35: 19410768 8540 599 01 | F35: 85.4 | G35: Felsőoktatás | H35: 85.4 | I35: Felsőoktatás | J35: 85 | K35: Oktatás | L35: Q | M35: OKTATÁS | N35: 599 | O35: Egyéb, jogi személyiségű nonprofit szervezet | P35: 59 | Q35: Egyéb, jogi személyiségű nonprofit szervezet | R35: 5 | S35: Jogi személyiségű nonprofit szervezet | T35: 1 | U35: Budapest | V35: 11 | W35: Budapest | X35: 1 | Y35: Közép-Magyarország | Z35: 2025 | AC35: 0 | AD35: ismeretlen | AE35: 0 | AF35: ismeretlen | AG35: 2021 - 2025 | AI35: 137 | AJ35: 137 | AK35: 137 | AL35: 137 | AM35: 137 | AN35: 137 | AO35: 137 | AP35: 137 | AQ35: 137 | AR35: 137 | AS35: 137 | AT35: 137 | AU35: 137 | AV35: 137 | AW35: 137 | AX35: 137 | AY35: 138 | AZ35: 138 | BA35: 137 | BB35: 137 | BC35: 137 | BD35: 137 | BE35: 137 | BF35: 138 | BG35: 138 | BH35: 138 | BI35: 138 | BJ35: 138 | BK35: 138 | BL35: 138 | BM35: 138 | BN35: 138 | BO35: 138 | BP35: 138 | BQ35: 138 | BR35: 138 | BS35: 138 | BT35: 138 | BU35: 138 | BV35: 138 | BW35: 138 | BX35: 138 | BY35: 138 | BZ35: 138 | CA35: 137.52273 | CB35: 138 | CC35: 0.50525777 | CD35: 0.0036739947 | CE35: 137 | CF35: 138 | CG35: 1 | CH35: 1 | CI35: 1
A36: 35 | B36: 18836 | C36: u-szeged.hu | D36: 19308650-2-06 | E36: 19308650 8540 563 06 | F36: 85.4 | G36: Felsőoktatás | H36: 85.4 | I36: Felsőoktatás | J36: 85 | K36: Oktatás | L36: Q | M36: OKTATÁS | N36: 563 | O36: Egyéb alapítvány önálló intézménye | P36: 56 | Q36: Alapítvány, jogi személyiségű intézménye és szervezeti egysége | R36: 5 | S36: Jogi személyiségű nonprofit szervezet | T36: 6 | U36: Csongrád-Csanád | V36: 70 | W36: Dél-Alföld | X36: 3 | Y36: Alföld és Észak | Z36: 2021 | AA36: 11589 | AC36: 95 | AD36: 5000- | AE36: 0 | AF36: ismeretlen | AG36: 2021 - 2025 | AI36: 6 | AJ36: 37 | AK36: 13 | AL36: 36 | AM36: 41 | AN36: 36 | AO36: 37 | AP36: 41 | AQ36: 14 | AR36: 42 | AS36: 42 | AT36: 41 | AU36: 14 | AV36: 14 | AW36: 13 | AX36: 13 | AY36: 12 | AZ36: 13 | BA36: 12 | BB36: 29 | BC36: 12 | BD36: 28 | BE36: 12 | BF36: 14 | BG36: 12 | BH36: 13 | BI36: 12 | BJ36: 41 | BK36: 13 | BL36: 41 | BM36: 41 | BN36: 41 | BO36: 12 | BP36: 41 | BQ36: 42 | BR36: 42 | BS36: 15 | BT36: 14 | BU36: 43 | BV36: 41 | BW36: 13 | BX36: 41 | BY36: 41 | BZ36: 41 | CA36: 26.636364 | CB36: 28.5 | CC36: 13.848165 | CD36: 0.51989697 | CE36: 6 | CF36: 43 | CG36: 37 | CH36: 35 | CI36: 35
A37: 36 | B37: 21897 | C37: starity.hu | D37: 23062595-2-18 | E37: 23062595 6310 113 18 | F37: 63.1 | G37: Számítástechnikai infrastruktúra, adatfeldolgozás, tárhelyszolgáltatás és kapcsolódó szolgáltatások | H37: 63.1 | I37: Számítástechnikai infrastruktúra, adatfeldolgozás, tárhelyszolgáltatás és kapcsolódó szolgáltatások | J37: 63 | K37: Számítástechnikai infrastruktúra, adatfeldolgozás, tárhelyszolgáltatás és egyéb információs szolgáltatási tevékenységek | L37: K | M37: TÁVKÖZLÉS, SZÁMÍTÓGÉPES PROGRAMOZÁS, INFORMÁCIÓTECHNOLÓGIAI SZAKTANÁCSADÁS, SZÁMÍTÁSTECHNIKAI INFRASTRUKTÚRA ÉS EGYÉB INFORMÁCIÓS SZOLGÁLTATÁSOK | N37: 113 | O37: Korlátolt felelősségű társaság | P37: 11 | Q37: Gazdasági társaság | R37: 1 | S37: Jogi személyiségű vállalkozás | T37: 18 | U37: Vas | V37: 30 | W37: Nyugat-Dunántúl | X37: 2 | Y37: Dunántúl | Z37: 2010 | AA37: 1 | AB37: 22260000 | AC37: 11 | AD37: 1 | AE37: 2 | AF37: 21 - 50 | AG37: 2006 - 2010 | AH37: mikrovállalkozás | AI37: 48 | AJ37: 52 | AK37: 49 | AL37: 48 | AM37: 47 | AN37: 46 | AO37: 49 | AP37: 49 | AQ37: 46 | AR37: 47 | AS37: 46 | AT37: 46 | AU37: 46 | AV37: 45 | AW37: 47 | AX37: 49 | AY37: 45 | AZ37: 46 | BA37: 45 | BB37: 48 | BC37: 48 | BD37: 47 | BE37: 48 | BF37: 48 | BG37: 47 | BH37: 47 | BI37: 46 | BJ37: 47 | BK37: 47 | BL37: 47 | BM37: 47 | BN37: 46 | BO37: 47 | BP37: 46 | BQ37: 47 | BR37: 45 | BS37: 45 | BT37: 46 | BU37: 47 | BV37: 46 | BW37: 47 | BX37: 47 | BY37: 47 | BZ37: 39 | CA37: 46.772727 | CB37: 47 | CC37: 1.802629 | CD37: 0.038540174 | CE37: 39 | CF37: 52 | CG37: 13 | CH37: -9 | CI37: 9
A38: 39 | B38: 25279 | C38: vatera.hu | D38: 32330681-2-41 | E38: 32330681 4779 113 01 | F38: 47.79 | G38: Használt cikk kiskereskedelme | H38: 47.7 | I38: Egyéb áruk kiskereskedelme (kivéve: gépjármű, motorkerékpár) | J38: 47 | K38: Kiskereskedelem | L38: G | M38: KERESKEDELEM | N38: 113 | O38: Korlátolt felelősségű társaság | P38: 11 | Q38: Gazdasági társaság | R38: 1 | S38: Jogi személyiségű vállalkozás | T38: 1 | U38: Budapest | V38: 11 | W38: Budapest | X38: 1 | Y38: Közép-Magyarország | Z38: 2023 | AA38: 21 | AB38: 578750000 | AC38: 40 | AD38: 20-49 | AE38: 5 | AF38: 501 - 700 | AG38: 2021 - 2025 | AH38: kisvállalkozás | AI38: 82 | AJ38: 82 | AK38: 82 | AL38: 85 | AM38: 85 | AN38: 84 | AO38: 84 | AP38: 92 | AQ38: 88 | AR38: 91 | AS38: 92 | AT38: 90 | AU38: 90 | AV38: 89 | AW38: 89 | AX38: 89 | AY38: 93 | AZ38: 89 | BA38: 88 | BB38: 89 | BC38: 88 | BD38: 88 | BE38: 87 | BF38: 87 | BG38: 94 | BH38: 91 | BI38: 95 | BJ38: 89 | BK38: 93 | BL38: 94 | BM38: 83 | BN38: 84 | BO38: 63 | BP38: 83 | BQ38: 83 | BR38: 83 | BS38: 80 | BT38: 74 | BU38: 69 | BV38: 69 | BW38: 67 | BX38: 70 | BY38: 69 | BZ38: 65 | CA38: 84.113636 | CB38: 87 | CC38: 8.5023004 | CD38: 0.10108112 | CE38: 63 | CF38: 95 | CG38: 32 | CH38: -17 | CI38: 17
A39: 40 | B39: 25729 | C39: profession.hu | D39: 25087879-2-44 | E39: 25087879 7312 113 01 | F39: 73.12 | G39: Médiareklám | H39: 73.1 | I39: Reklám | J39: 73 | K39: Reklám, piackutatás, PR-tevékenység | L39: N | M39: SZAKMAI, TUDOMÁNYOS, MŰSZAKI TEVÉKENYSÉG | N39: 113 | O39: Korlátolt felelősségű társaság | P39: 11 | Q39: Gazdasági társaság | R39: 1 | S39: Jogi személyiségű vállalkozás | T39: 1 | U39: Budapest | V39: 11 | W39: Budapest | X39: 1 | Y39: Közép-Magyarország | Z39: 2014 | AA39: 224 | AB39: 15895330000 | AC39: 70 | AD39: 200-249 | AE39: C | AF39: 10001 - | AG39: 2011 - 2015 | AH39: középvállalkozás | AI39: 33 | AJ39: 33 | AK39: 33 | AL39: 33 | AM39: 33 | AN39: 32 | AO39: 33 | AP39: 32 | AQ39: 33 | AR39: 32 | AS39: 32 | AT39: 32 | AU39: 32 | AV39: 31 | AW39: 32 | AX39: 32 | AY39: 33 | AZ39: 33 | BA39: 32 | BB39: 33 | BC39: 32 | BD39: 32 | BE39: 32 | BF39: 32 | BG39: 13 | BH39: 32 | BI39: 32 | BJ39: 32 | BK39: 32 | BL39: 32 | BM39: 32 | BN39: 32 | BO39: 32 | BP39: 32 | BQ39: 32 | BR39: 32 | BS39: 32 | BT39: 32 | BU39: 32 | BV39: 32 | BW39: 31 | BX39: 31 | BY39: 31 | BZ39: 31 | CA39: 31.681818 | CB39: 32 | CC39: 2.9394884 | CD39: 0.092781556 | CE39: 13 | CF39: 33 | CG39: 20 | CH39: -2 | CI39: 2
A40: 41 | B40: 26017 | C40: magyarhirlap.hu | D40: 13389909-2-42 | E40: 13389909 5812 113 01 | F40: 58.12 | G40: Napilapkiadás | H40: 58.1 | I40: Könyv-, napilapkiadás, egyéb kiadói tevékenység (kivéve: szoftverkiadás) | J40: 58 | K40: Kiadói tevékenység | L40: J | M40: KIADÓI TEVÉKENYSÉG, MŰSORSZOLGÁLTATÁS, TARTALOMSZOLGÁLTATÁS ÉS -TERJESZTÉS | N40: 113 | O40: Korlátolt felelősségű társaság | P40: 11 | Q40: Gazdasági társaság | R40: 1 | S40: Jogi személyiségű vállalkozás | T40: 1 | U40: Budapest | V40: 11 | W40: Budapest | X40: 1 | Y40: Közép-Magyarország | Z40: 2004 | AA40: 20 | AB40: 402450000 | AC40: 40 | AD40: 20-49 | AE40: 4 | AF40: 301 - 500 | AG40: 2001 - 2005 | AH40: kisvállalkozás | AI40: 68 | AJ40: 68 | AK40: 67 | AL40: 67 | AM40: 67 | AN40: 69 | AO40: 67 | AP40: 67 | AQ40: 67 | AR40: 67 | AS40: 67 | AT40: 67 | AU40: 67 | AV40: 67 | AW40: 67 | AX40: 66 | AY40: 66 | AZ40: 67 | BA40: 67 | BB40: 67 | BC40: 67 | BD40: 66 | BE40: 67 | BF40: 66 | BG40: 66 | BH40: 68 | BI40: 67 | BJ40: 65 | BK40: 64 | BL40: 65 | BM40: 65 | BN40: 66 | BO40: 66 | BP40: 70 | BQ40: 73 | BR40: 72 | BS40: 69 | BT40: 66 | BU40: 68 | BV40: 68 | BW40: 69 | BX40: 68 | BY40: 67 | BZ40: 67 | CA40: 67.204545 | CB40: 67 | CC40: 1.6364958 | CD40: 0.024350968 | CE40: 64 | CF40: 73 | CG40: 9 | CH40: -1 | CI40: 1
A41: 42 | B41: 26453 | C41: magyarnemzet.hu | D41: 24785725-2-44 | E41: 24785725 5812 114 01 | F41: 58.12 | G41: Napilapkiadás | H41: 58.1 | I41: Könyv-, napilapkiadás, egyéb kiadói tevékenység (kivéve: szoftverkiadás) | J41: 58 | K41: Kiadói tevékenység | L41: J | M41: KIADÓI TEVÉKENYSÉG, MŰSORSZOLGÁLTATÁS, TARTALOMSZOLGÁLTATÁS ÉS -TERJESZTÉS | N41: 114 | O41: Részvénytársaság | P41: 11 | Q41: Gazdasági társaság | R41: 1 | S41: Jogi személyiségű vállalkozás | T41: 1 | U41: Budapest | V41: 11 | W41: Budapest | X41: 1 | Y41: Közép-Magyarország | Z41: 2013 | AA41: 1974 | AB41: 57098150000 | AC41: 93 | AD41: 1000-1999 | AE41: C | AF41: 10001 - | AG41: 2011 - 2015 | AH41: nagyvállalat | AI41: 17 | AJ41: 14 | AK41: 17 | AL41: 17 | AM41: 16 | AN41: 18 | AO41: 17 | AP41: 18 | AQ41: 16 | AR41: 15 | AS41: 17 | AT41: 16 | AU41: 18 | AV41: 19 | AW41: 15 | AX41: 17 | AY41: 27 | AZ41: 15 | BA41: 19 | BB41: 25 | BC41: 26 | BD41: 25 | BE41: 23 | BF41: 28 | BG41: 23 | BH41: 30 | BI41: 22 | BJ41: 29 | BK41: 26 | BL41: 27 | BM41: 21 | BN41: 24 | BO41: 18 | BP41: 26 | BQ41: 24 | BR41: 26 | BS41: 18 | BT41: 18 | BU41: 24 | BV41: 24 | BW41: 25 | BX41: 251 | BY41: 163 | BZ41: 170 | CA41: 32.818182 | CB41: 21.5 | CC41: 45.741576 | CD41: 1.3937876 | CE41: 14 | CF41: 251 | CG41: 237 | CH41: 153 | CI41: 153
A42: 43 | B42: 27782 | C42: metropol.hu | D42: 24785725-2-44 | E42: 24785725 5812 114 01 | F42: 58.12 | G42: Napilapkiadás | H42: 58.1 | I42: Könyv-, napilapkiadás, egyéb kiadói tevékenység (kivéve: szoftverkiadás) | J42: 58 | K42: Kiadói tevékenység | L42: J | M42: KIADÓI TEVÉKENYSÉG, MŰSORSZOLGÁLTATÁS, TARTALOMSZOLGÁLTATÁS ÉS -TERJESZTÉS | N42: 114 | O42: Részvénytársaság | P42: 11 | Q42: Gazdasági társaság | R42: 1 | S42: Jogi személyiségű vállalkozás | T42: 1 | U42: Budapest | V42: 11 | W42: Budapest | X42: 1 | Y42: Közép-Magyarország | Z42: 2013 | AA42: 1974 | AB42: 57098150000 | AC42: 93 | AD42: 1000-1999 | AE42: C | AF42: 10001 - | AG42: 2011 - 2015 | AH42: nagyvállalat | AI42: 65 | AJ42: 66 | AK42: 62 | AL42: 62 | AM42: 63 | AN42: 63 | AO42: 63 | AP42: 63 | AQ42: 63 | AR42: 60 | AS42: 60 | AT42: 56 | AU42: 56 | AV42: 56 | AW42: 56 | AX42: 56 | AY42: 56 | AZ42: 56 | BA42: 56 | BB42: 56 | BC42: 56 | BD42: 55 | BE42: 56 | BF42: 57 | BG42: 57 | BH42: 63 | BI42: 59 | BJ42: 62 | BK42: 62 | BL42: 60 | BM42: 60 | BN42: 60 | BO42: 60 | BP42: 60 | BQ42: 60 | BR42: 62 | BS42: 62 | BT42: 62 | BU42: 47 | BV42: 47 | BW42: 46 | BX42: 51 | BY42: 51 | BZ42: 52 | CA42: 58.204545 | CB42: 60 | CC42: 4.7767827 | CD42: 0.082068895 | CE42: 46 | CF42: 66 | CG42: 20 | CH42: -13 | CI42: 13
A43: 44 | B43: 27818 | C43: kormany.hu | D43: 10585560-2-44 | E43: 10585560 6290 114 01 | F43: 62.9 | G43: Egyéb információtechnológiai szolgáltatás | H43: 62.9 | I43: Egyéb információtechnológiai szolgáltatás | J43: 62 | K43: Információtechnológiai szolgáltatás | L43: K | M43: TÁVKÖZLÉS, SZÁMÍTÓGÉPES PROGRAMOZÁS, INFORMÁCIÓTECHNOLÓGIAI SZAKTANÁCSADÁS, SZÁMÍTÁSTECHNIKAI INFRASTRUKTÚRA ÉS EGYÉB INFORMÁCIÓS SZOLGÁLTATÁSOK | N43: 114 | O43: Részvénytársaság | P43: 11 | Q43: Gazdasági társaság | R43: 1 | S43: Jogi személyiségű vállalkozás | T43: 1 | U43: Budapest | V43: 11 | W43: Budapest | X43: 1 | Y43: Közép-Magyarország | Z43: 1991 | AA43: 1162 | AB43: 96765620000 | AC43: 93 | AD43: 1000-1999 | AE43: C | AF43: 10001 - | AG43: 1991 - 1995 | AH43: nagyvállalat | AI43: 18 | AJ43: 18 | AK43: 13 | AL43: 14 | AM43: 14 | AN43: 19 | AO43: 19 | AP43: 19 | AQ43: 19 | AR43: 18 | AS43: 18 | AT43: 18 | AU43: 18 | AV43: 18 | AW43: 18 | AX43: 18 | AY43: 18 | AZ43: 18 | BA43: 18 | BB43: 18 | BC43: 18 | BD43: 18 | BE43: 18 | BF43: 0 | BG43: 0 | BH43: 0 | BI43: 0 | BJ43: 0 | BK43: 0 | BL43: 0 | BM43: 0 | BN43: 0 | BO43: 0 | BP43: 0 | BQ43: 0 | BR43: 0 | BS43: 0 | BT43: 0 | BU43: 0 | BV43: 0 | BW43: 0 | BX43: 0 | BY43: 0 | BZ43: 0 | CA43: 9.2045455 | CB43: 13.5 | CC43: 8.9717374 | CD43: 0.97470727 | CE43: 0 | CF43: 19 | CG43: 19 | CH43: -18 | CI43: 18
